<?xml version="1.0" encoding="utf-8"?>
<!-- This URDF was automatically created by SolidWorks to URDF Exporter! Originally created by Stephen Brawner (brawner@gmail.com) 
     Commit Version: 1.6.0-1-g15f4949  Build Version: 1.6.7594.29634
     For more information, please see http://wiki.ros.org/sw_urdf_exporter -->
<robot
  name="myool_urdf">
  <link
    name="myool_chassis">
    <inertial>
      <origin
        xyz="-0.0025949 0 0.003175"
        rpy="0 0 0" />
      <mass
        value="2.8701" />
      <inertia
        ixx="0.019918"
        ixy="5.8875E-18"
        ixz="-8.948E-19"
        iyy="0.042638"
        iyz="2.3451E-19"
        izz="0.061874" />
    </inertial>
    <visual>
      <origin
        xyz="0 0 0"
        rpy="0 0 0" />
      <geometry>
        <box size="0.42 0.345 0.007" />
      </geometry>
      <material
        name="">
        <color
          rgba="0.75294 0.75294 0.75294 1" />
      </material>
    </visual>
    <collision>
      <origin
        xyz="0 0 0"
        rpy="0 0 0" />
      <geometry>
        <box size="0.42 0.345 0.08" />
      </geometry>
    </collision>
  </link>
  <link
    name="myool_front_right_wheel">
    <inertial>
      <origin
        xyz="-5.5511E-17 -0.021778 -6.245E-17"
        rpy="0 0 0" />
      <mass
        value="0.84556" />
      <inertia
        ixx="0.001557"
        ixy="1.505E-19"
        ixz="3.8952E-11"
        iyy="0.0028888"
        iyz="2.8717E-09"
        izz="0.001557" />
    </inertial>
    <visual>
      <origin
        xyz="0 0 0"
        rpy="90 0 0" />
      <geometry>
        <cylinder length="0.0435" radius="0.085"/>
      </geometry>
      <material
        name="">
        <color
          rgba="0.79216 0.81961 0.93333 1" />
      </material>
    </visual>
    <collision>
      <origin
        xyz="0 0 0"
        rpy="90 0 0" />
      <geometry>
        <cylinder length="0.0435" radius="0.085"/>
      </geometry>
    </collision>
  </link>
  <joint
    name="myool_front_right_joint"
    type="continuous">
    <origin
      xyz="0.14829 -0.21561 0.003175"
      rpy="0 0 0" />
    <parent
      link="myool_chassis" />
    <child
      link="myool_front_right_wheel" />
    <axis
      xyz="0 1 0" />
  </joint>
   <link
    name="myool_front_left_wheel">
    <inertial>
      <origin
        xyz="-1.1102E-16 0.021778 9.7145E-17"
        rpy="0 0 0" />
      <mass
        value="0.84556" />
      <inertia
        ixx="0.001557"
        ixy="1.0003E-18"
        ixz="-3.8952E-11"
        iyy="0.0028888"
        iyz="-2.8717E-09"
        izz="0.001557" />
    </inertial>
    <visual>
      <origin
        xyz="0 0 0"
        rpy="90 0 0" />
      <geometry>
        <cylinder length="0.0435" radius="0.085"/>
      </geometry>
      <material
        name="">
        <color
          rgba="0.79216 0.81961 0.93333 1" />
      </material>
    </visual>
    <collision>
      <origin
        xyz="0 0 0"
        rpy="90 0 0" />
      <geometry>
        <cylinder length="0.0435" radius="0.085"/>
      </geometry>
    </collision>
  </link>
  <joint
    name="myool_front_left_joint"
    type="continuous">
    <origin
      xyz="0.14829 0.21561 0.003175"
      rpy="0 0 0" />
    <parent
      link="myool_chassis" />
    <child
      link="myool_front_left_wheel" />
    <axis
      xyz="0 -1 0" />
  </joint>
   <link
    name="myool_rear_right_rocker">
    <inertial>
      <origin
        xyz="2.067E-17 -0.0031974 -1.9429E-16"
        rpy="0 0 0" />
      <mass
        value="0.32911" />
      <inertia
        ixx="0.00015526"
        ixy="1.4694E-20"
        ixz="-1.017E-19"
        iyy="0.0020318"
        iyz="3.0888E-21"
        izz="0.0018788" />
    </inertial>
    <visual>
      <origin
        xyz="0 0 0"
        rpy="0 0 0" />
      <geometry>
        <box size="0.28 0.01 0.08" />
      </geometry>
      <material
        name="">
        <color
          rgba="0.89804 0.91765 0.92941 1" />
      </material>
    </visual>
    <collision>
      <origin
        xyz="0 0 0"
        rpy="0 0 0" />
      <geometry>
        <box size="0.28 0.01 0.08" />
      </geometry>
    </collision>
  </link>
  <joint
    name="myool_rear_right_joint"
    type="continuous">
    <origin
      xyz="-0.15651 -0.20097 0.003175"
      rpy="0 0 0" />
    <parent
      link="myool_chassis" />
    <child
      link="myool_rear_right_rocker" />
    <axis
      xyz="0 1 0" />
  </joint>
  <link
    name="myool_rear_right_rocker_rear_wheel">
    <inertial>
      <origin
        xyz="-1.3878E-17 -0.021778 -6.9389E-18"
        rpy="0 0 0" />
      <mass
        value="0.84556" />
      <inertia
        ixx="0.001557"
        ixy="1.1E-09"
        ixz="2.7521E-11"
        iyy="0.0028888"
        iyz="2.6527E-09"
        izz="0.001557" />
    </inertial>
    <visual>
      <origin
        xyz="0 0 0"
        rpy="90 0 0" />
      <geometry>
        <cylinder length="0.0435" radius="0.085"/>
      </geometry>
      <material
        name="">
        <color
          rgba="0.79216 0.81961 0.93333 1" />
      </material>
    </visual>
    <collision>
      <origin
        xyz="0 0 0"
        rpy="90 0 0" />
      <geometry>
        <cylinder length="0.0435" radius="0.085"/>
      </geometry>
    </collision>
  </link>
  <joint
    name="myool_rear_right_rocker_rear_joint"
    type="continuous">
    <origin
      xyz="-0.1016 -0.01465 0"
      rpy="0 0 0" />
    <parent
      link="myool_rear_right_rocker" />
    <child
      link="myool_rear_right_rocker_rear_wheel" />
    <axis
      xyz="0 1 0" />
  </joint> 
    <link
    name="myool_rear_right_rocker_center_wheel">
    <inertial>
      <origin
        xyz="-1.3878E-17 -0.021778 -2.0817E-17"
        rpy="0 0 0" />
      <mass
        value="0.84556" />
      <inertia
        ixx="0.001557"
        ixy="1.1E-09"
        ixz="2.7521E-11"
        iyy="0.0028888"
        iyz="2.6527E-09"
        izz="0.001557" />
    </inertial>
    <visual>
      <origin
        xyz="0 0 0"
        rpy="90 0 0" />
      <geometry>
        <cylinder length="0.0435" radius="0.085"/>
      </geometry>
      <material
        name="">
        <color
          rgba="0.79216 0.81961 0.93333 1" />
      </material>
    </visual>
    <collision>
      <origin
        xyz="0 0 0"
        rpy="90 0 0" />
      <geometry>
        <cylinder length="0.0435" radius="0.085"/>
      </geometry>
    </collision>
  </link>
  <joint
    name="myool_rear_right_rocker_center_joint"
    type="continuous">
    <origin
      xyz="0.1016 -0.01465 0"
      rpy="0 0 0" />
    <parent
      link="myool_rear_right_rocker" />
    <child
      link="myool_rear_right_rocker_center_wheel" />
    <axis
      xyz="0 1 0" />
  </joint>
  <link
    name="myool_rear_left_rocker">
    <inertial>
      <origin
        xyz="4.3112E-17 0.0031526 -1.9429E-16"
        rpy="0 0 0" />
      <mass
        value="0.32911" />
      <inertia
        ixx="0.00015526"
        ixy="2.8787E-22"
        ixz="-1.0017E-19"
        iyy="0.0020318"
        iyz="3.2183E-21"
        izz="0.0018788" />
    </inertial>
    <visual>
      <origin
        xyz="0 0 0"
        rpy="0 0 0" />
      <geometry>
        <box size="0.28 0.01 0.08" />
      </geometry>
      <material
        name="">
        <color
          rgba="0.89804 0.91765 0.92941 1" />
      </material>
    </visual>
    <collision>
      <origin
        xyz="0 0 0"
        rpy="0 0 0" />
      <geometry>
        <box size="0.28 0.01 0.08" />
      </geometry>
    </collision>
  </link>
  <joint
    name="myool_rear_left_joint"
    type="continuous">
    <origin
      xyz="-0.15651 0.20097 0.003175"
      rpy="0 0 0" />
    <parent
      link="myool_chassis" />
    <child
      link="myool_rear_left_rocker" />
    <axis
      xyz="0 1 0" />
  </joint>
  <link
    name="myool_rear_left_rocker_rear_wheel">
    <inertial>
      <origin
        xyz="1.3878E-17 0.021778 -1.3878E-17"
        rpy="0 0 0" />
      <mass
        value="0.84556" />
      <inertia
        ixx="0.001557"
        ixy="7.9382E-20"
        ixz="-3.8952E-11"
        iyy="0.0028888"
        iyz="-2.8717E-09"
        izz="0.001557" />
    </inertial>
    <visual>
      <origin
        xyz="0 0 0"
        rpy="90 0 0" />
      <geometry>
        <cylinder length="0.0435" radius="0.085"/>
      </geometry>
      <material
        name="">
        <color
          rgba="0.79216 0.81961 0.93333 1" />
      </material>
    </visual>
    <collision>
      <origin
        xyz="0 0 0"
        rpy="90 0 0" />
      <geometry>
        <cylinder length="0.0435" radius="0.085"/>
      </geometry>
    </collision>
  </link>
  <joint
    name="myool_rear_left_rocker_rear_joint"
    type="continuous">
    <origin
      xyz="-0.1016 0.01465 0"
      rpy="0 0 0" />
    <parent
      link="myool_rear_left_rocker" />
    <child
      link="myool_rear_left_rocker_rear_wheel" />
    <axis
      xyz="0 -1 0" />
  </joint>
  <link
    name="myool_rear_left_rocker_center_wheel">
    <inertial>
      <origin
        xyz="-2.7756E-17 0.021778 -1.1102E-16"
        rpy="0 0 0" />
      <mass
        value="0.84556" />
      <inertia
        ixx="0.001557"
        ixy="-1.4318E-19"
        ixz="-3.8952E-11"
        iyy="0.0028888"
        iyz="-2.8717E-09"
        izz="0.001557" />
    </inertial>
    <visual>
      <origin
        xyz="0 0 0"
        rpy="90 0 0" />
      <geometry>
        <cylinder length="0.0435" radius="0.085"/>
      </geometry>
      <material
        name="">
        <color
          rgba="0.79216 0.81961 0.93333 1" />
      </material>
    </visual>
    <collision>
      <origin
        xyz="0 0 0"
        rpy="90 0 0" />
      <geometry>
        <cylinder length="0.0435" radius="0.085"/>
      </geometry>
    </collision>
  </link>
  <joint
    name="myool_rear_left_rocker_center_joint"
    type="continuous">
    <origin
      xyz="0.1016 0.01465 0"
      rpy="0 0 0" />
    <parent
      link="myool_rear_left_rocker" />
    <child
      link="myool_rear_left_rocker_center_wheel" />
    <axis
      xyz="0 -1 0" />
  </joint>
  <link
    name="myool_battery">
    <inertial>
      <origin
        xyz="0 0 0"
        rpy="0 0 0" />
      <mass
        value="0" />
      <inertia
        ixx="0"
        ixy="0"
        ixz="0"
        iyy="0"
        iyz="0"
        izz="0" />
    </inertial>
    <visual>
      <origin
        xyz="0 0 0"
        rpy="0 0 0" />
      <geometry>
        <box size="0.285 0.20 0.075" />
      </geometry>
      <material
        name="">
        <color
          rgba="1 1 1 1" />
      </material>
    </visual>
    <collision>
      <origin
        xyz="0 0 0"
        rpy="0 0 0" />
      <geometry>
        <box size="0.285 0.20 0.075" />
      </geometry>
    </collision>
  </link>
  <joint
    name="myool_battery_joint"
    type="fixed">
    <origin
      xyz="-0.097493 0.025146 0.00635"
      rpy="0 0 0" />
    <parent
      link="myool_chassis" />
    <child
      link="myool_battery" />
    <axis
      xyz="0 0 0" />
  </joint>  
</robot>