<?xml version="1.0" encoding="utf-8"?>
<!-- This URDF was automatically created by SolidWorks to URDF Exporter! Originally created by Stephen Brawner (brawner@gmail.com) 
     Commit Version: 1.6.0-1-g15f4949  Build Version: 1.6.7594.29634
     For more information, please see http://wiki.ros.org/sw_urdf_exporter -->
<robot
  name="myool_urdf">
  <link
    name="myool_chassis">
    <inertial>
      <origin
        xyz="-0.0025949 0 0.003175"
        rpy="0 0 0" />
      <mass
        value="2.8701" />
      <inertia
        ixx="0.019918"
        ixy="5.8875E-18"
        ixz="-8.948E-19"
        iyy="0.042638"
        iyz="2.3451E-19"
        izz="0.061874" />
    </inertial>
    <visual>
      <origin
        xyz="0 0 0"
        rpy="0 0 0" />
      <geometry>
        <box size="0.42 0.345 0.007" />
      </geometry>
      <material
        name="">
        <color
          rgba="0.75294 0.75294 0.75294 1" />
      </material>
    </visual>
    <collision>
      <origin
        xyz="0 0 0"
        rpy="0 0 0" />
      <geometry>
        <box size="0.42 0.345 0.08" />
      </geometry>
    </collision>
  </link>
  <link
    name="myool_front_right_wheel">
    <inertial>
      <origin
        xyz="-5.5511E-17 -0.021778 -6.245E-17"
        rpy="0 0 0" />
      <mass
        value="0.84556" />
      <inertia
        ixx="0.001557"
        ixy="1.505E-19"
        ixz="3.8952E-11"
        iyy="0.0028888"
        iyz="2.8717E-09"
        izz="0.001557" />
    </inertial>
    <visual>
      <origin
        xyz="0 0 0"
        rpy="0 0 0" />
      <geometry>
        <cylinder length="0.0435" radius="0.17"/>
      </geometry>
      <material
        name="">
        <color
          rgba="0.79216 0.81961 0.93333 1" />
      </material>
    </visual>
    <collision>
      <origin
        xyz="0 0 0"
        rpy="0 0 0" />
      <geometry>
        <cylinder length="0.0435" radius="0.85"/>
      </geometry>
    </collision>
  </link>
  <joint
    name="myool_front_right_joint"
    type="continuous">
    <origin
      xyz="0.14829 -0.21561 0.003175"
      rpy="0 0 0" />
    <parent
      link="myool_chassis" />
    <child
      link="myool_front_right_wheel" />
    <axis
      xyz="0 1 0" />
  </joint>
</robot>