<?xml version="1.0" encoding="utf-8"?>
<!-- This URDF was automatically created by SolidWorks to URDF Exporter! Originally created by Stephen Brawner (brawner@gmail.com) 
     Commit Version: 1.6.0-1-g15f4949  Build Version: 1.6.7594.29634
     For more information, please see http://wiki.ros.org/sw_urdf_exporter -->
<robot
  name="myool_urdf">
  
  <material name="black">
    <color rgba="0.0 0.0 0.0 1.0"/>
  </material>
  <material name="blue">
    <color rgba="0.203125 0.23828125 0.28515625 1.0"/>
  </material>
  <material name="green">
    <color rgba="0.0 0.8 0.0 1.0"/>
  </material>
  <material name="grey">
    <color rgba="0.2 0.2 0.2 1.0"/>
  </material>
  <material name="orange">
    <color rgba="1.0 0.423529411765 0.0392156862745 1.0"/>
  </material>
  <material name="brown">
    <color rgba="0.870588235294 0.811764705882 0.764705882353 1.0"/>
  </material>
  <material name="red">
    <color rgba="0.80078125 0.12890625 0.1328125 1.0"/>
  </material>
  <material name="white">
    <color rgba="1.0 1.0 1.0 1.0"/>
  </material>
  
  <gazebo reference="myool_chassis">
    <material>Gazebo/Orange</material>
  </gazebo>
  <gazebo reference="myool_front_right_wheel">
    <material>Gazebo/Black</material>
  </gazebo>
  <gazebo reference="myool_front_left_wheel">
    <material>Gazebo/Black</material>
  </gazebo>  
  <gazebo reference="myool_rear_right_rocker_rear_wheel">
    <material>Gazebo/Black</material>
  </gazebo>  
  <gazebo reference="myool_rear_right_rocker_center_wheel">
    <material>Gazebo/Black</material>
  </gazebo>  
  <gazebo reference="myool_rear_left_rocker_rear_wheel">
    <material>Gazebo/Black</material>
  </gazebo>  
  <gazebo reference="myool_rear_left_rocker_center_wheel">
    <material>Gazebo/Black</material>
  </gazebo>  
  <gazebo reference="myool_battery">
    <material>Gazebo/Blue</material>
  </gazebo>    

  <gazebo>
    <plugin filename="libgazebo_ros_diff_drive.so" name="differential_drive_controller">
      <legacyMode>false</legacyMode>
      <alwaysOn>true</alwaysOn>
      <updateRate>20</updateRate>
      <leftJoint>myool_rear_left_rocker_center_joint</leftJoint>
	  <leftJoint>myool_front_left_joint</leftJoint>
	  <leftJoint>myool_rear_left_rocker_rear_joint</leftJoint>
      <rightJoint>myool_rear_right_rocker_rear_joint</rightJoint>
	  <rightJoint>myool_front_right_joint</rightJoint>
	  <rightJoint>myool_rear_right_rocker_center_joint</rightJoint>
      <wheelSeparation>0.47472</wheelSeparation>
      <wheelDiameter>0.170</wheelDiameter>
      <torque>3.0</torque>
      <commandTopic>cmd_vel</commandTopic>
      <odometryTopic>odom</odometryTopic>
      <odometryFrame>odom</odometryFrame>
      <robotBaseFrame>myool_chassis</robotBaseFrame>
    </plugin>
  </gazebo>
<!-- 
<gazebo>
  <plugin name="skid_steer_drive_controller" filename="libgazebo_ros_skid_steer_drive.so">
    <updateRate>20</updateRate>
    <robotNamespace>/</robotNamespace>
    <leftFrontJoint>myool_front_left_joint</leftFrontJoint>
    <rightFrontJoint>myool_front_right_joint</rightFrontJoint>
    <leftRearJoint>myool_rear_left_rocker_center_joint</leftRearJoint>
    <rightRearJoint>myool_rear_right_rocker_center_joint</rightRearJoint>
    <wheelSeparation>0.47472</wheelSeparation>
    <wheelDiameter>0.170</wheelDiameter>
    <robotBaseFrame>myool_chassis</robotBaseFrame>
    <torque>2</torque>
    <topicName>cmd_vel</topicName>
    <broadcastTF>false</broadcastTF>
  </plugin>
</gazebo>
--> 
  <link
    name="myool_chassis">
	<pose>0 0 0.08 0 0 0</pose>
    <inertial>
      <origin
        xyz="0 0 0"
        rpy="0 0 0" />
      <mass
        value="2.8701" />
      <inertia
        ixx="0.019918"
        ixy="0"
        ixz="0"
        iyy="0.042638"
        iyz="0"
        izz="0.061874" />
    </inertial>
    <visual>
      <origin
        xyz="0 0 0"
        rpy="0 0 0" />
      <geometry>
        <box size="0.42 0.345 0.007" />
      </geometry>
      <material
        name="orange">
      </material>
    </visual>
    <collision>
      <origin
        xyz="0 0 0"
        rpy="0 0 0" />
      <geometry>
        <box size="0.42 0.345 0.007" />
      </geometry>
    </collision>
  </link>
  <link
    name="myool_front_right_wheel">
    <inertial>
      <origin
        xyz="0 0 0"
        rpy="0 1.5707 1.5707" />
      <mass
        value="2.2" />
      <inertia
        ixx="0.005892"
        ixy="0"
        ixz="0"
        iyy="0.005892"
        iyz="0"
        izz="0.010838" />
    </inertial>
    <visual>
      <origin
        xyz="0 0 0"
        rpy="0 1.5707 1.5707" />
      <geometry>
        <cylinder length="0.0435" radius="0.085"/>
      </geometry>
      <material
        name="black">
      </material>
    </visual>
    <collision>
      <origin
        xyz="0 0 0"
        rpy="0 1.5707 1.5707" />
      <geometry>
        <cylinder length="0.0435" radius="0.085"/>
      </geometry>
    </collision>
  </link>
  <joint
    name="myool_front_right_joint"
    type="continuous">
    <origin
      xyz="0.14829 -0.23736 0.003175"
      rpy="0 0 0" />
    <parent
      link="myool_chassis" />
    <child
      link="myool_front_right_wheel" />
    <axis
      xyz="0 1 0" />
	<limit effort="10000" velocity="1000"/>
    <joint_properties damping="1.0" friction="1.0"/>
  </joint>
   <link
    name="myool_front_left_wheel">
    <inertial>
      <origin
        xyz="0 0 0"
        rpy="0 1.5707 1.5707" />
      <mass
        value="2.2" />
      <inertia
        ixx="0.005892"
        ixy="0"
        ixz="0"
        iyy="0.005892"
        iyz="0"
        izz="0.010838" />
	</inertial>
    <visual>
      <origin
        xyz="0 0 0"
        rpy="0 1.5707 1.5707" />
      <geometry>
        <cylinder length="0.0435" radius="0.085"/>
      </geometry>
      <material
        name="black">
      </material>
    </visual>
    <collision>
      <origin
        xyz="0 0 0"
        rpy="0 1.5707 1.5707" />
      <geometry>
        <cylinder length="0.0435" radius="0.085"/>
      </geometry>
    </collision>
  </link>
  <joint
    name="myool_front_left_joint"
    type="continuous">
    <origin
      xyz="0.14829 0.23736 0.003175"
      rpy="0 0 0" />
    <parent
      link="myool_chassis" />
    <child
      link="myool_front_left_wheel" />
    <axis
      xyz="0 1 0" />
	<limit effort="10000" velocity="1000"/>
    <joint_properties damping="1.0" friction="1.0"/>  
  </joint>
   <link
    name="myool_rear_right_rocker">
    <inertial>
      <origin
        xyz="0 0 0"
        rpy="0 0 0" />
      <mass
        value="0.32911" />
      <inertia
        ixx="0.00015526"
        ixy="0"
        ixz="0"
        iyy="0.0020318"
        iyz="0"
        izz="0.0018788" />
    </inertial>
    <visual>
      <origin
        xyz="0 0 0"
        rpy="0 0 0" />
      <geometry>
        <box size="0.28 0.01 0.08" />
      </geometry>
      <material
        name="white">
      </material>
    </visual>
    <collision>
      <origin
        xyz="0 0 0"
        rpy="0 0 0" />
      <geometry>
        <box size="0.28 0.01 0.08" />
      </geometry>
    </collision>
  </link>
  <joint
    name="myool_rear_right_joint"
    type="continuous">
    <origin
      xyz="-0.15651 -0.20097 0.003175"
      rpy="0 0 0" />
    <parent
      link="myool_chassis" />
    <child
      link="myool_rear_right_rocker" />
    <axis
      xyz="0 1 0" />
  </joint>
  <link
    name="myool_rear_right_rocker_rear_wheel">
    <inertial>
      <origin
        xyz="0 0 0"
        rpy="0 1.5707 1.5707" />
      <mass
        value="2.2" />
      <inertia
        ixx="0.005892"
        ixy="0"
        ixz="0"
        iyy="0.005892"
        iyz="0"
        izz="0.010838" />
    </inertial>
    <visual>
      <origin
        xyz="0 0 0"
        rpy="0 1.5707 1.5707" />
      <geometry>
        <cylinder length="0.0435" radius="0.085"/>
      </geometry>
      <material
        name="black">
      </material>
    </visual>
    <collision>
      <origin
        xyz="0 0 0"
        rpy="0 1.5707 1.5707" />
      <geometry>
        <cylinder length="0.0435" radius="0.085"/>
      </geometry>
    </collision>
  </link>
  <joint
    name="myool_rear_right_rocker_rear_joint"
    type="continuous">
    <origin
      xyz="-0.1016 -0.0364 0"
      rpy="0 0 0" />
    <parent
      link="myool_rear_right_rocker" />
    <child
      link="myool_rear_right_rocker_rear_wheel" />
    <axis
      xyz="0 1 0" />
	<limit effort="10000" velocity="1000"/>
    <joint_properties damping="1.0" friction="1.0"/>
  </joint> 
    <link
    name="myool_rear_right_rocker_center_wheel">
    <inertial>
      <origin
        xyz="0 0 0"
        rpy="0 1.5707 1.5707" />
      <mass
        value="2.2" />
      <inertia
        ixx="0.005892"
        ixy="0"
        ixz="0"
        iyy="0.005892"
        iyz="0"
        izz="0.010838" />
    </inertial>
    <visual>
      <origin
        xyz="0 0 0"
        rpy="0 1.5707 1.5707" />
      <geometry>
        <cylinder length="0.0435" radius="0.085"/>
      </geometry>
      <material
        name="black">
      </material>
    </visual>
    <collision>
      <origin
        xyz="0 0 0"
        rpy="0 1.5707 1.5707" />
      <geometry>
        <cylinder length="0.0435" radius="0.085"/>
      </geometry>
    </collision>
  </link>
  <joint
    name="myool_rear_right_rocker_center_joint"
    type="continuous">
    <origin
      xyz="0.1016 -0.0364 0"
      rpy="0 0 0" />
    <parent
      link="myool_rear_right_rocker" />
    <child
      link="myool_rear_right_rocker_center_wheel" />
    <axis
      xyz="0 1 0" />
	<limit effort="10000" velocity="1000"/>
    <joint_properties damping="1.0" friction="1.0"/>  
  </joint>
  <link
    name="myool_rear_left_rocker">
    <inertial>
      <origin
        xyz="0 0 0"
        rpy="0 0 0" />
      <mass
        value="0.32911" />
      <inertia
        ixx="0.00015526"
        ixy="0"
        ixz="0"
        iyy="0.0020318"
        iyz="0"
        izz="0.0018788" />
    </inertial>
    <visual>
      <origin
        xyz="0 0 0"
        rpy="0 0 0" />
      <geometry>
        <box size="0.28 0.01 0.08" />
      </geometry>
      <material
        name="white">
      </material>
    </visual>
    <collision>
      <origin
        xyz="0 0 0"
        rpy="0 0 0" />
      <geometry>
        <box size="0.28 0.01 0.08" />
      </geometry>
    </collision>
  </link>
  <joint
    name="myool_rear_left_joint"
    type="continuous">
    <origin
      xyz="-0.15651 0.20097 0.003175"
      rpy="0 0 0" />
    <parent
      link="myool_chassis" />
    <child
      link="myool_rear_left_rocker" />
    <axis
      xyz="0 1 0" />
  </joint>
  <link
    name="myool_rear_left_rocker_rear_wheel">
    <inertial>
      <origin
        xyz="0 0 0"
        rpy="0 1.5707 1.5707" />
      <mass
        value="2.2" />
      <inertia
        ixx="0.005892"
        ixy="0"
        ixz="0"
        iyy="0.005892"
        iyz="0"
        izz="0.010838" />
    </inertial>
    <visual>
      <origin
        xyz="0 0 0"
        rpy="0 1.5707 1.5707" />
      <geometry>
        <cylinder length="0.0435" radius="0.085"/>
      </geometry>
      <material
        name="black">
      </material>
    </visual>
    <collision>
      <origin
        xyz="0 0 0"
        rpy="0 1.5707 1.5707" />
      <geometry>
        <cylinder length="0.0435" radius="0.085"/>
      </geometry>
    </collision>
  </link>
  <joint
    name="myool_rear_left_rocker_rear_joint"
    type="continuous">
    <origin
      xyz="-0.1016 0.0364 0"
      rpy="0 0 0" />
    <parent
      link="myool_rear_left_rocker" />
    <child
      link="myool_rear_left_rocker_rear_wheel" />
    <axis
      xyz="0 1 0" />
	<limit effort="10000" velocity="1000"/>
    <joint_properties damping="1.0" friction="1.0"/>  
  </joint>
  <link
    name="myool_rear_left_rocker_center_wheel">
    <inertial>
      <origin
        xyz="0 0 0"
        rpy="0 1.5707 1.5707" />
      <mass
        value="2.2" />
      <inertia
        ixx="0.005892"
        ixy="0"
        ixz="0"
        iyy="0.005892"
        iyz="0"
        izz="0.010838" />
    </inertial>
    <visual>
      <origin
        xyz="0 0 0"
        rpy="0 1.5707 1.5707" />
      <geometry>
        <cylinder length="0.0435" radius="0.085"/>
      </geometry>
      <material
        name="black">
      </material>
    </visual>
    <collision>
      <origin
        xyz="0 0 0"
        rpy="0 1.5707 1.5707" />
      <geometry>
        <cylinder length="0.0435" radius="0.085"/>
      </geometry>
    </collision>
  </link>
  <joint
    name="myool_rear_left_rocker_center_joint"
    type="continuous">
    <origin
      xyz="0.1016 0.0364 0"
      rpy="0 0 0" />
    <parent
      link="myool_rear_left_rocker" />
    <child
      link="myool_rear_left_rocker_center_wheel" />
    <axis
      xyz="0 1 0" />
	<limit effort="10000" velocity="1000"/>
    <joint_properties damping="1.0" friction="1.0"/>  
  </joint>
  <link
    name="myool_battery">
    <inertial>
      <origin
        xyz="0 0 0"
        rpy="0 0 0" />
      <mass
        value="7" />
      <inertia
        ixx="6.716561"
        ixy="0"
        ixz="0"
        iyy="13.36388"
        iyz="0"
        izz="4.891684" />
    </inertial>
    <visual>
      <origin
        xyz="0 0 0"
        rpy="0 0 0" />
      <geometry>
        <box size="0.285 0.20 0.075" />
      </geometry>
      <material
        name="blue">
      </material>
    </visual>
    <collision>
      <origin
        xyz="0 0 0"
        rpy="0 0 0" />
      <geometry>
        <box size="0.285 0.20 0.075" />
      </geometry>
    </collision>
  </link>
  <joint
    name="myool_battery_joint"
    type="fixed">
    <origin
      xyz="0 0 0.0375"
      rpy="0 0 0" />
    <parent
      link="myool_chassis" />
    <child
      link="myool_battery" />
    <axis
      xyz="0 0 0" />
  </joint>  
</robot>